2020-05-23 01:29:57,862 ERROR: Exception on /submit [GET] [in c:\users\tyco1\appdata\local\programs\python\python38-32\lib\site-packages\flask\app.py:1890]
Traceback (most recent call last):
  File "c:\users\tyco1\appdata\local\programs\python\python38-32\lib\site-packages\flask\app.py", line 2446, in wsgi_app
    response = self.full_dispatch_request()
  File "c:\users\tyco1\appdata\local\programs\python\python38-32\lib\site-packages\flask\app.py", line 1951, in full_dispatch_request
    rv = self.handle_user_exception(e)
  File "c:\users\tyco1\appdata\local\programs\python\python38-32\lib\site-packages\flask\app.py", line 1820, in handle_user_exception
    reraise(exc_type, exc_value, tb)
  File "c:\users\tyco1\appdata\local\programs\python\python38-32\lib\site-packages\flask\_compat.py", line 39, in reraise
    raise value
  File "c:\users\tyco1\appdata\local\programs\python\python38-32\lib\site-packages\flask\app.py", line 1949, in full_dispatch_request
    rv = self.dispatch_request()
  File "c:\users\tyco1\appdata\local\programs\python\python38-32\lib\site-packages\flask\app.py", line 1935, in dispatch_request
    return self.view_functions[rule.endpoint](**req.view_args)
  File "C:\Users\tyco1\Desktop\VirtualFridge-master-new\app\main\routes.py", line 28, in submit
    return render_template('submit.html', title='Submit')
  File "c:\users\tyco1\appdata\local\programs\python\python38-32\lib\site-packages\flask\templating.py", line 138, in render_template
    ctx.app.jinja_env.get_or_select_template(template_name_or_list),
  File "c:\users\tyco1\appdata\local\programs\python\python38-32\lib\site-packages\jinja2\environment.py", line 930, in get_or_select_template
    return self.get_template(template_name_or_list, parent, globals)
  File "c:\users\tyco1\appdata\local\programs\python\python38-32\lib\site-packages\jinja2\environment.py", line 883, in get_template
    return self._load_template(name, self.make_globals(globals))
  File "c:\users\tyco1\appdata\local\programs\python\python38-32\lib\site-packages\jinja2\environment.py", line 857, in _load_template
    template = self.loader.load(self, name, globals)
  File "c:\users\tyco1\appdata\local\programs\python\python38-32\lib\site-packages\jinja2\loaders.py", line 117, in load
    source, filename, uptodate = self.get_source(environment, name)
  File "c:\users\tyco1\appdata\local\programs\python\python38-32\lib\site-packages\flask\templating.py", line 60, in get_source
    return self._get_source_fast(environment, template)
  File "c:\users\tyco1\appdata\local\programs\python\python38-32\lib\site-packages\flask\templating.py", line 89, in _get_source_fast
    raise TemplateNotFound(template)
jinja2.exceptions.TemplateNotFound: submit.html
2020-05-23 01:30:09,666 ERROR: Exception on /home [GET] [in c:\users\tyco1\appdata\local\programs\python\python38-32\lib\site-packages\flask\app.py:1890]
Traceback (most recent call last):
  File "c:\users\tyco1\appdata\local\programs\python\python38-32\lib\site-packages\flask\app.py", line 2446, in wsgi_app
    response = self.full_dispatch_request()
  File "c:\users\tyco1\appdata\local\programs\python\python38-32\lib\site-packages\flask\app.py", line 1951, in full_dispatch_request
    rv = self.handle_user_exception(e)
  File "c:\users\tyco1\appdata\local\programs\python\python38-32\lib\site-packages\flask\app.py", line 1820, in handle_user_exception
    reraise(exc_type, exc_value, tb)
  File "c:\users\tyco1\appdata\local\programs\python\python38-32\lib\site-packages\flask\_compat.py", line 39, in reraise
    raise value
  File "c:\users\tyco1\appdata\local\programs\python\python38-32\lib\site-packages\flask\app.py", line 1949, in full_dispatch_request
    rv = self.dispatch_request()
  File "c:\users\tyco1\appdata\local\programs\python\python38-32\lib\site-packages\flask\app.py", line 1935, in dispatch_request
    return self.view_functions[rule.endpoint](**req.view_args)
  File "c:\users\tyco1\appdata\local\programs\python\python38-32\lib\site-packages\flask_login\utils.py", line 272, in decorated_view
    return func(*args, **kwargs)
  File "C:\Users\tyco1\Desktop\VirtualFridge-master-new\app\main\routes.py", line 16, in home
    return render_template('home.html', title='Home')
  File "c:\users\tyco1\appdata\local\programs\python\python38-32\lib\site-packages\flask\templating.py", line 137, in render_template
    return _render(
  File "c:\users\tyco1\appdata\local\programs\python\python38-32\lib\site-packages\flask\templating.py", line 120, in _render
    rv = template.render(context)
  File "c:\users\tyco1\appdata\local\programs\python\python38-32\lib\site-packages\jinja2\environment.py", line 1090, in render
    self.environment.handle_exception()
  File "c:\users\tyco1\appdata\local\programs\python\python38-32\lib\site-packages\jinja2\environment.py", line 832, in handle_exception
    reraise(*rewrite_traceback_stack(source=source))
  File "c:\users\tyco1\appdata\local\programs\python\python38-32\lib\site-packages\jinja2\_compat.py", line 28, in reraise
    raise value.with_traceback(tb)
  File "C:\Users\tyco1\Desktop\VirtualFridge-master-new\app\templates\home.html", line 1, in top-level template code
    {% extends "layout.html" %}
  File "C:\Users\tyco1\Desktop\VirtualFridge-master-new\app\templates\layout.html", line 37, in top-level template code
    <li> <a href="{{ url_for('logout') }}"><span class="glyphicon glyphicon-log-out"></span>Logout</a> </li>
  File "c:\users\tyco1\appdata\local\programs\python\python38-32\lib\site-packages\flask\helpers.py", line 370, in url_for
    return appctx.app.handle_url_build_error(error, endpoint, values)
  File "c:\users\tyco1\appdata\local\programs\python\python38-32\lib\site-packages\flask\app.py", line 2215, in handle_url_build_error
    reraise(exc_type, exc_value, tb)
  File "c:\users\tyco1\appdata\local\programs\python\python38-32\lib\site-packages\flask\_compat.py", line 39, in reraise
    raise value
  File "c:\users\tyco1\appdata\local\programs\python\python38-32\lib\site-packages\flask\helpers.py", line 357, in url_for
    rv = url_adapter.build(
  File "c:\users\tyco1\appdata\local\programs\python\python38-32\lib\site-packages\werkzeug\routing.py", line 2179, in build
    raise BuildError(endpoint, values, method, self)
werkzeug.routing.BuildError: Could not build url for endpoint 'logout'. Did you mean 'auth.logout' instead?
2020-05-23 01:30:35,502 ERROR: Exception on /home [GET] [in c:\users\tyco1\appdata\local\programs\python\python38-32\lib\site-packages\flask\app.py:1890]
Traceback (most recent call last):
  File "c:\users\tyco1\appdata\local\programs\python\python38-32\lib\site-packages\flask\app.py", line 2446, in wsgi_app
    response = self.full_dispatch_request()
  File "c:\users\tyco1\appdata\local\programs\python\python38-32\lib\site-packages\flask\app.py", line 1951, in full_dispatch_request
    rv = self.handle_user_exception(e)
  File "c:\users\tyco1\appdata\local\programs\python\python38-32\lib\site-packages\flask\app.py", line 1820, in handle_user_exception
    reraise(exc_type, exc_value, tb)
  File "c:\users\tyco1\appdata\local\programs\python\python38-32\lib\site-packages\flask\_compat.py", line 39, in reraise
    raise value
  File "c:\users\tyco1\appdata\local\programs\python\python38-32\lib\site-packages\flask\app.py", line 1949, in full_dispatch_request
    rv = self.dispatch_request()
  File "c:\users\tyco1\appdata\local\programs\python\python38-32\lib\site-packages\flask\app.py", line 1935, in dispatch_request
    return self.view_functions[rule.endpoint](**req.view_args)
  File "c:\users\tyco1\appdata\local\programs\python\python38-32\lib\site-packages\flask_login\utils.py", line 272, in decorated_view
    return func(*args, **kwargs)
  File "C:\Users\tyco1\Desktop\VirtualFridge-master-new\app\main\routes.py", line 16, in home
    return render_template('home.html', title='Home')
  File "c:\users\tyco1\appdata\local\programs\python\python38-32\lib\site-packages\flask\templating.py", line 137, in render_template
    return _render(
  File "c:\users\tyco1\appdata\local\programs\python\python38-32\lib\site-packages\flask\templating.py", line 120, in _render
    rv = template.render(context)
  File "c:\users\tyco1\appdata\local\programs\python\python38-32\lib\site-packages\jinja2\environment.py", line 1090, in render
    self.environment.handle_exception()
  File "c:\users\tyco1\appdata\local\programs\python\python38-32\lib\site-packages\jinja2\environment.py", line 832, in handle_exception
    reraise(*rewrite_traceback_stack(source=source))
  File "c:\users\tyco1\appdata\local\programs\python\python38-32\lib\site-packages\jinja2\_compat.py", line 28, in reraise
    raise value.with_traceback(tb)
  File "C:\Users\tyco1\Desktop\VirtualFridge-master-new\app\templates\home.html", line 1, in top-level template code
    {% extends "layout.html" %}
  File "C:\Users\tyco1\Desktop\VirtualFridge-master-new\app\templates\layout.html", line 37, in top-level template code
    <li> <a href="{{ url_for('auth.logout') }}"><span class="glyphicon glyphicon-log-out"></span>Logout</a> </li>
  File "c:\users\tyco1\appdata\local\programs\python\python38-32\lib\site-packages\flask\helpers.py", line 370, in url_for
    return appctx.app.handle_url_build_error(error, endpoint, values)
  File "c:\users\tyco1\appdata\local\programs\python\python38-32\lib\site-packages\flask\app.py", line 2215, in handle_url_build_error
    reraise(exc_type, exc_value, tb)
  File "c:\users\tyco1\appdata\local\programs\python\python38-32\lib\site-packages\flask\_compat.py", line 39, in reraise
    raise value
  File "c:\users\tyco1\appdata\local\programs\python\python38-32\lib\site-packages\flask\helpers.py", line 357, in url_for
    rv = url_adapter.build(
  File "c:\users\tyco1\appdata\local\programs\python\python38-32\lib\site-packages\werkzeug\routing.py", line 2179, in build
    raise BuildError(endpoint, values, method, self)
werkzeug.routing.BuildError: Could not build url for endpoint 'logout'. Did you mean 'auth.logout' instead?
