2020-06-01 16:24:23,683 ERROR: Exception on /edit_profile [GET] [in c:\users\tyco1\appdata\local\programs\python\python38-32\lib\site-packages\flask\app.py:1890]
Traceback (most recent call last):
  File "c:\users\tyco1\appdata\local\programs\python\python38-32\lib\site-packages\flask\app.py", line 2446, in wsgi_app
    response = self.full_dispatch_request()
  File "c:\users\tyco1\appdata\local\programs\python\python38-32\lib\site-packages\flask\app.py", line 1951, in full_dispatch_request
    rv = self.handle_user_exception(e)
  File "c:\users\tyco1\appdata\local\programs\python\python38-32\lib\site-packages\flask\app.py", line 1820, in handle_user_exception
    reraise(exc_type, exc_value, tb)
  File "c:\users\tyco1\appdata\local\programs\python\python38-32\lib\site-packages\flask\_compat.py", line 39, in reraise
    raise value
  File "c:\users\tyco1\appdata\local\programs\python\python38-32\lib\site-packages\flask\app.py", line 1949, in full_dispatch_request
    rv = self.dispatch_request()
  File "c:\users\tyco1\appdata\local\programs\python\python38-32\lib\site-packages\flask\app.py", line 1935, in dispatch_request
    return self.view_functions[rule.endpoint](**req.view_args)
  File "c:\users\tyco1\appdata\local\programs\python\python38-32\lib\site-packages\flask_login\utils.py", line 272, in decorated_view
    return func(*args, **kwargs)
  File "C:\Users\tyco1\Desktop\VirtualFridge-master-V1\app\main\routes.py", line 63, in edit_profile
    return render_template('edit_profile.html', title='Edit Profile', form=form)
  File "c:\users\tyco1\appdata\local\programs\python\python38-32\lib\site-packages\flask\templating.py", line 137, in render_template
    return _render(
  File "c:\users\tyco1\appdata\local\programs\python\python38-32\lib\site-packages\flask\templating.py", line 120, in _render
    rv = template.render(context)
  File "c:\users\tyco1\appdata\local\programs\python\python38-32\lib\site-packages\jinja2\environment.py", line 1090, in render
    self.environment.handle_exception()
  File "c:\users\tyco1\appdata\local\programs\python\python38-32\lib\site-packages\jinja2\environment.py", line 832, in handle_exception
    reraise(*rewrite_traceback_stack(source=source))
  File "c:\users\tyco1\appdata\local\programs\python\python38-32\lib\site-packages\jinja2\_compat.py", line 28, in reraise
    raise value.with_traceback(tb)
  File "C:\Users\tyco1\Desktop\VirtualFridge-master-V1\app\templates\edit_profile.html", line 1, in top-level template code
    {% extends "layout.html" %}
  File "C:\Users\tyco1\Desktop\VirtualFridge-master-V1\app\templates\layout.html", line 43, in top-level template code
    {% block content %}
  File "C:\Users\tyco1\Desktop\VirtualFridge-master-V1\app\templates\edit_profile.html", line 17, in block "content"
    {{ form.data(size=32) }}<br>
TypeError: 'dict' object is not callable
2020-06-01 16:28:52,861 INFO: Virtualfridge startup [in C:\Users\tyco1\Desktop\VirtualFridge-master-V1\app\__init__.py:70]
2020-06-01 16:31:13,185 INFO: Virtualfridge startup [in C:\Users\tyco1\Desktop\VirtualFridge-master-V1\app\__init__.py:70]
2020-06-03 02:58:53,025 INFO: Virtualfridge startup [in C:\Users\tyco1\Desktop\VirtualFridge-master-V1\app\__init__.py:70]
2020-06-03 02:58:56,375 INFO: Virtualfridge startup [in C:\Users\tyco1\Desktop\VirtualFridge-master-V1\app\__init__.py:70]
2020-06-03 02:58:56,375 INFO: Virtualfridge startup [in C:\Users\tyco1\Desktop\VirtualFridge-master-V1\app\__init__.py:70]
